<?xml version="1.0"?>
<!-- Copyright 2019 The DSuite Authors.

Licensed under the Apache License, Version 2.0 (the "License");
you may not use this file except in compliance with the License.
You may obtain a copy of the License at

    http://www.apache.org/licenses/LICENSE-2.0

Unless required by applicable law or agreed to in writing, software
distributed under the License is distributed on an "AS IS" BASIS,
WITHOUT WARRANTIES OR CONDITIONS OF ANY KIND, either express or implied.
See the License for the specific language governing permissions and
limitations under the License. -->
<mujocoinclude>
  <body name="_dclaw" pos="0 0 0" euler="3.14 0 0.523599" childclass="overlay">
    <geom mesh="metal_circle"/>
    <body name="_FFtop" pos="-0.001 -0.052 .016">
      <geom mesh="plastic_top" pos="0 0 0"/>
      <body name="_FFbase" pos="0 -0.01 0.020" euler="0 0 3.14">
        <geom mesh="xh28" pos="0 0 0"/>
        <body name="_FF0" pos="0 0 0.058">
          <geom mesh="xh28" pos="0 0 0" euler="1.57 1.57 0"/>
          <geom mesh="metal_clamping_small" pos="0 0 -0.012" euler="3.14 0 0"/>
          <joint name="_FFJ0" type="hinge" pos="0 0 0" axis="0 0 1"/>
          <body name="_FFL1" pos="0 0 0">
            <geom mesh="xh28" pos="0 0 0.068" euler="1.57 1.57 0"/>
            <geom mesh="metal_clamping_small" pos="0 0 0.0555" euler="3.14 0 0"/>
            <geom mesh="metal_clamping" pos="0 0 0"/>
            <joint name="_FFJ1" type="hinge" pos="0 0 0" axis="1 0 0" limited="true" range="-2.14 2.14"/>
            <body name="_FFL2" pos="0 0 0.068">
              <geom mesh="metal_clamping" pos="0 0 0"/>
              <geom mesh="plastic_finger" pos="0 0 0.046"/>
              <joint name="_FFJ2" type="hinge" pos="0 0 0" axis="1 0 0" limited="true" range="-2.14 2.14"/>
              <site name="_FFtip" type="sphere" pos="0 0 .076" size="0.01" rgba="1 .3 .3 1"/>
            </body>
          </body>
        </body>
      </body>
    </body>
    <body name="_MFtop" pos=".044 0.025  0.016" euler="0 0 2.0944">
      <geom mesh="plastic_top" pos="0 0 0"/>
      <body name="_MFbase" pos="0 -0.01 0.020" euler="0 0 3.14">
        <geom mesh="xh28" pos="0 0 0"/>
        <body name="_MF0" pos="0 0 0.058">
          <geom mesh="xh28" pos="0 0 0" euler="1.57 1.57 0"/>
          <geom mesh="metal_clamping_small" pos="0 0 -0.012" euler="3.14 0 0"/>
          <joint name="_MFJ0" type="hinge" pos="0 0 0" axis="0 0 1"/>
          <body name="_MFL1" pos="0 0 0">
            <geom mesh="xh28" pos="0 0 0.068" euler="1.57 1.57 0"/>
            <geom mesh="metal_clamping_small" pos="0 0 0.0555" euler="3.14 0 0"/>
            <geom mesh="metal_clamping" pos="0 0 0"/>
            <joint name="_MFJ1" type="hinge" pos="0 0 0" axis="1 0 0" limited="true" range="-2.14 2.14"/>
            <body name="_MFL2" pos="0 0 0.068">
              <geom mesh="metal_clamping" pos="0 0 0"/>
              <geom mesh="plastic_finger" pos="0 0 0.046"/>
              <joint name="_MFJ2" type="hinge" pos="0 0 0" axis="1 0 0" limited="true" range="-2.14 2.14"/>
              <site name="_MFtip" type="sphere" pos="0 0 .076" size="0.01" rgba=".3 1 .3 1"/>
            </body>
          </body>
        </body>
      </body>
    </body>
    <body name="_TFtop" pos="-.044 0.025  0.016" euler="0 0 -2.0944">
      <geom mesh="plastic_top" pos="0 0 0"/>
      <body name="_THbase" pos="0 -0.01 0.020" euler="0 0 3.14">
        <geom mesh="xh28" pos="0 0 0"/>
        <body name="_TH0" pos="0 0 0.058">
          <geom mesh="xh28" pos="0 0 0" euler="1.57 1.57 0"/>
          <geom mesh="metal_clamping_small" pos="0 0 -0.012" euler="3.14 0 0"/>
          <joint name="_THJ0" type="hinge" pos="0 0 0" axis="0 0 1"/>
          <body name="_THL1" pos="0 0 0">
            <geom mesh="xh28" pos="0 0 0.068" euler="1.57 1.57 0"/>
            <geom mesh="metal_clamping_small" pos="0 0 0.0555" euler="3.14 0 0"/>
            <geom mesh="metal_clamping" pos="0 0 0"/>
            <joint name="_THJ1" type="hinge" pos="0 0 0" axis="1 0 0" limited="true" range="-2.14 2.14"/>
            <body name="_THL2" pos="0 0 0.068">
              <geom mesh="metal_clamping" pos="0 0 0"/>
              <geom mesh="plastic_finger" pos="0 0 0.046"/>
              <joint name="_THJ2" type="hinge" pos="0 0 0" axis="1 0 0" limited="true" range="-2.14 2.14"/>
              <site name="_THtip" type="sphere" pos="0 0 .076" size="0.01" rgba=".3 .3 1 1"/>
            </body>
          </body>
        </body>
      </body>
    </body>
  </body>
</mujocoinclude>
