<?xml version="1.0"?>
<!--
 ~ Copyright 2019 The D'Suite Authors.
 ~
 ~ Licensed under the Apache License, Version 2.0 (the "License");
 ~ you may not use this file except in compliance with the License.
 ~ You may obtain a copy of the License at
 ~
 ~     http://www.apache.org/licenses/LICENSE-2.0
 ~
 ~ Unless required by applicable law or agreed to in writing, software
 ~ distributed under the License is distributed on an "AS IS" BASIS,
 ~ WITHOUT WARRANTIES OR CONDITIONS OF ANY KIND, either express or implied.
 ~ See the License for the specific language governing permissions and
 ~ limitations under the License.
 -->
<mujocoinclude>
  <body name="kitty" childclass="dkitty">
    <!-- Torso -->
    <geom name="torso1" class="viz_metal_black" type="mesh" mesh="torso" pos="0 0 .01" rgba=".9 .9 .9 1"/>
    <geom class="phy_metal" type="box" pos="0 0 .027" size=".102 .140 .0175" mass=".500"/>
    <!-- Front Right Foot -->
    <body name="FR0" pos=".09 -.1215 0.093" euler="0 0 3.14">
      <geom class="viz_metal_black" mesh="metal_clamping_small" pos="0 0 0.015" euler="3.14 0 0"/>
      <geom class="viz_metal_black" mesh="metal_clamping" pos="0 0 -.067" euler="0 0 1.57"/>
      <geom class="viz_metal_black" mesh="xh28" pos="0 0 0.027" euler="1.57 1.57 0"/>
      <geom class="phy_metal" mesh="xh28_hull" pos="0 0 0.027" euler="1.57 1.57 0" mass="0.082"/>
      <geom class="phy_metal" type="box" pos="0.0 0  -0.012" size="0.018 0.014 0.001"/>
      <geom class="phy_metal" type="box" pos="0.019 0 -0.007" size="0.0008 0.014 0.006"/>
      <geom class="phy_metal" type="box" pos="-0.019 0 -0.007" size="0.0008 0.014 0.006"/>
      <joint name="FRJ0" type="hinge" pos="0 0 -0.0656" axis="0 1 0" limited="true" range="-.50 .35"/>
      <body name="FRL1" pos="0 0 0.027">
        <geom class="viz_metal_black" mesh="metal_clamping_small" pos="0 0 0.0825" euler="3.14 0 0"/>
        <geom class="viz_metal_black" mesh="xh28" pos="0 0 0.095" euler="1.57 1.57 0"/>
        <geom class="phy_metal" mesh="xh28_hull" pos="0 0 0.095" euler="1.57 1.57 0" mass="0.082"/>
        <geom class="phy_metal" type="box" pos="0.0 0  0.0535" size="0.018 0.014 0.004"/>
        <geom class="viz_metal_black" mesh="metal_clamping" pos="0 0 0"/>
        <geom class="phy_metal" type="box" pos="0.02 0 0.0255" size="0.0015 0.012 0.028"/>
        <geom class="phy_metal" type="box" pos="-0.02 0 0.0255" size="0.0015 0.012 0.028"/>
        <geom class="phy_metal" type="box" pos="0.019 0 0.062" size="0.0008 0.014 0.0055"/>
        <geom class="phy_metal" type="box" pos="-0.019 0 0.062" size="0.0008 0.014 0.0055"/>
        <joint name="FRJ1" type="hinge" pos="0 0 0" axis="1 0 0" limited="true" range="0 1.57"/>
        <body name="FRL2" pos="0 0 0.095">
          <geom class="viz_metal_black" mesh="metal_clamping" pos="0 0 0"/>
          <geom class="phy_metal" type="box" pos="0.02 0 0.0255" size="0.0015 0.012 0.026"/>
          <geom class="phy_metal" type="box" pos="-0.02 0 0.0255" size="0.0015 0.012 0.026"/>
          <geom class="viz_plastic" mesh="plastic_finger" pos="0 0 0.074"/>
          <geom class="phy_plastic" type="capsule" pos="0 0 0.083" size="0.01 0.02"/>
          <geom class="phy_plastic" type="box" pos="0 0 0.056" size="0.0245 0.014 0.0055"/>
          <joint name="FRJ2" type="hinge" pos="0 0 0" axis="1 0 0" limited="true" range="-2.14 0"/>
          <site name="FRtip" type="sphere" pos="0 0 .076" size="0.01" rgba=".3 .3 1 1"/>
        </body>
      </body>
    </body>
    <!-- Back Right Foot -->
    <body name="BR0" pos=".09 .1215 0.093" euler="0 0 3.14">
      <geom class="viz_metal_black" mesh="metal_clamping_small" pos="0 0 0.015" euler="3.14 0 0"/>
      <geom class="viz_metal_black" mesh="metal_clamping" pos="0 0 -.067" euler="0 0 1.57"/>
      <geom class="viz_metal_black" mesh="xh28" pos="0 0 0.027" euler="1.57 1.57 0"/>
      <geom class="phy_metal" mesh="xh28_hull" pos="0 0 0.027" euler="1.57 1.57 0" mass="0.082"/>
      <geom class="phy_metal" type="box" pos="0.0 0  -0.012" size="0.018 0.014 0.001"/>
      <geom class="phy_metal" type="box" pos="0.019 0 -0.007" size="0.0008 0.014 0.006"/>
      <geom class="phy_metal" type="box" pos="-0.019 0 -0.007" size="0.0008 0.014 0.006"/>
      <joint name="BRJ0" type="hinge" pos="0 0 -0.0656" axis="0 1 0" limited="true" range="-.50 .35"/>
      <body name="BRL1" pos="0 0 0.027">
        <geom class="viz_metal_black" mesh="metal_clamping_small" pos="0 0 0.0825" euler="3.14 0 0"/>
        <geom class="viz_metal_black" mesh="xh28" pos="0 0 0.095" euler="1.57 1.57 0"/>
        <geom class="phy_metal" mesh="xh28_hull" pos="0 0 0.095" euler="1.57 1.57 0" mass="0.082"/>
        <geom class="phy_metal" type="box" pos="0.0 0  0.0535" size="0.018 0.014 0.004"/>
        <geom class="viz_metal_black" mesh="metal_clamping" pos="0 0 0"/>
        <geom class="phy_metal" type="box" pos="0.02 0 0.0255" size="0.0015 0.012 0.028"/>
        <geom class="phy_metal" type="box" pos="-0.02 0 0.0255" size="0.0015 0.012 0.028"/>
        <geom class="phy_metal" type="box" pos="0.019 0 0.062" size="0.0008 0.014 0.0055"/>
        <geom class="phy_metal" type="box" pos="-0.019 0 0.062" size="0.0008 0.014 0.0055"/>
        <joint name="BRJ1" type="hinge" pos="0 0 0" axis="1 0 0" limited="true" range="0 1.57"/>
        <body name="BRL2" pos="0 0 0.095">
          <geom class="viz_metal_black" mesh="metal_clamping" pos="0 0 0"/>
          <geom class="phy_metal" type="box" pos="0.02 0 0.0255" size="0.0015 0.012 0.026"/>
          <geom class="phy_metal" type="box" pos="-0.02 0 0.0255" size="0.0015 0.012 0.026"/>
          <geom class="viz_plastic" mesh="plastic_finger" pos="0 0 0.074"/>
          <geom class="phy_plastic" type="capsule" pos="0 0 0.083" size="0.01 0.02"/>
          <geom class="phy_plastic" type="box" pos="0 0 0.056" size="0.0245 0.014 0.0055"/>
          <joint name="BRJ2" type="hinge" pos="0 0 0" axis="1 0 0" limited="true" range="-2.14 0"/>
          <site name="BRtip" type="sphere" pos="0 0 .076" size="0.01" rgba=".3 .3 1 1"/>
        </body>
      </body>
    </body>
    <!-- Front Left Foot -->
    <body name="FL0" pos="-.09 -.1215 0.093" euler="0 0 3.14">
      <geom class="viz_metal_black" mesh="metal_clamping_small" pos="0 0 0.015" euler="3.14 0 0"/>
      <geom class="viz_metal_black" mesh="metal_clamping" pos="0 0 -.067" euler="0 0 1.57"/>
      <geom class="viz_metal_black" mesh="xh28" pos="0 0 0.027" euler="1.57 1.57 0"/>
      <geom class="phy_metal" mesh="xh28_hull" pos="0 0 0.027" euler="1.57 1.57 0" mass="0.082"/>
      <geom class="phy_metal" type="box" pos="0.0 0  -0.012" size="0.018 0.014 0.001"/>
      <geom class="phy_metal" type="box" pos="0.019 0 -0.007" size="0.0008 0.014 0.006"/>
      <geom class="phy_metal" type="box" pos="-0.019 0 -0.007" size="0.0008 0.014 0.006"/>
      <joint name="FLJ0" type="hinge" pos="0 0 -0.0656" axis="0 -1 0" limited="true" range="-.50 .35"/>
      <body name="FLL1" pos="0 0 0.027">
        <geom class="viz_metal_black" mesh="metal_clamping_small" pos="0 0 0.0825" euler="3.14 0 0"/>
        <geom class="viz_metal_black" mesh="xh28" pos="0 0 0.095" euler="1.57 1.57 0"/>
        <geom class="phy_metal" mesh="xh28_hull" pos="0 0 0.095" euler="1.57 1.57 0" mass="0.082"/>
        <geom class="phy_metal" type="box" pos="0.0 0  0.0535" size="0.018 0.014 0.004"/>
        <geom class="viz_metal_black" mesh="metal_clamping" pos="0 0 0"/>
        <geom class="phy_metal" type="box" pos="0.02 0 0.0255" size="0.0015 0.012 0.028"/>
        <geom class="phy_metal" type="box" pos="-0.02 0 0.0255" size="0.0015 0.012 0.028"/>
        <geom class="phy_metal" type="box" pos="0.019 0 0.062" size="0.0008 0.014 0.0055"/>
        <geom class="phy_metal" type="box" pos="-0.019 0 0.062" size="0.0008 0.014 0.0055"/>
        <joint name="FLJ1" type="hinge" pos="0 0 0" axis="1 0 0" limited="true" range="0 1.57"/>
        <body name="FLL2" pos="0 0 0.095">
          <geom class="viz_metal_black" mesh="metal_clamping" pos="0 0 0"/>
          <geom class="phy_metal" type="box" pos="0.02 0 0.0255" size="0.0015 0.012 0.026"/>
          <geom class="phy_metal" type="box" pos="-0.02 0 0.0255" size="0.0015 0.012 0.026"/>
          <geom class="viz_plastic" mesh="plastic_finger" pos="0 0 0.074"/>
          <geom class="phy_plastic" type="capsule" pos="0 0 0.083" size="0.01 0.02"/>
          <geom class="phy_plastic" type="box" pos="0 0 0.056" size="0.0245 0.014 0.0055"/>
          <joint name="FLJ2" type="hinge" pos="0 0 0" axis="1 0 0" limited="true" range="-2.14 0"/>
          <site name="FLtip" type="sphere" pos="0 0 .076" size="0.01" rgba=".3 .3 1 1"/>
        </body>
      </body>
    </body>
    <!-- Left back Foot -->
    <body name="BL0" pos="-.09 .1215 0.093" euler="0 0 3.14">
      <geom class="viz_metal_black" mesh="metal_clamping_small" pos="0 0 0.015" euler="3.14 0 0"/>
      <geom class="viz_metal_black" mesh="metal_clamping" pos="0 0 -.067" euler="0 0 1.57"/>
      <geom class="viz_metal_black" mesh="xh28" pos="0 0 0.027" euler="1.57 1.57 0"/>
      <geom class="phy_metal" mesh="xh28_hull" pos="0 0 0.027" euler="1.57 1.57 0" mass="0.082"/>
      <geom class="phy_metal" type="box" pos="0.0 0  -0.012" size="0.018 0.014 0.001"/>
      <geom class="phy_metal" type="box" pos="0.019 0 -0.007" size="0.0008 0.014 0.006"/>
      <geom class="phy_metal" type="box" pos="-0.019 0 -0.007" size="0.0008 0.014 0.006"/>
      <joint name="BLJ0" type="hinge" pos="0 0 -0.0656" axis="0 -1 0" limited="true" range="-.50 .35"/>
      <body name="BLL1" pos="0 0 0.027">
        <geom class="viz_metal_black" mesh="metal_clamping_small" pos="0 0 0.0825" euler="3.14 0 0"/>
        <geom class="viz_metal_black" mesh="xh28" pos="0 0 0.095" euler="1.57 1.57 0"/>
        <geom class="phy_metal" mesh="xh28_hull" pos="0 0 0.095" euler="1.57 1.57 0" mass="0.082"/>
        <geom class="phy_metal" type="box" pos="0.0 0  0.0535" size="0.018 0.014 0.004"/>
        <geom class="viz_metal_black" mesh="metal_clamping" pos="0 0 0"/>
        <geom class="phy_metal" type="box" pos="0.02 0 0.0255" size="0.0015 0.012 0.028"/>
        <geom class="phy_metal" type="box" pos="-0.02 0 0.0255" size="0.0015 0.012 0.028"/>
        <geom class="phy_metal" type="box" pos="0.019 0 0.062" size="0.0008 0.014 0.0055"/>
        <geom class="phy_metal" type="box" pos="-0.019 0 0.062" size="0.0008 0.014 0.0055"/>
        <joint name="BLJ1" type="hinge" pos="0 0 0" axis="1 0 0" limited="true" range="0 1.57"/>
        <body name="BLL2" pos="0 0 0.095">
          <geom class="viz_metal_black" mesh="metal_clamping" pos="0 0 0"/>
          <geom class="phy_metal" type="box" pos="0.02 0 0.0255" size="0.0015 0.012 0.026"/>
          <geom class="phy_metal" type="box" pos="-0.02 0 0.0255" size="0.0015 0.012 0.026"/>
          <geom class="viz_plastic" mesh="plastic_finger" pos="0 0 0.074"/>
          <geom class="phy_plastic" type="capsule" pos="0 0 0.083" size="0.01 0.02"/>
          <geom class="phy_plastic" type="box" pos="0 0 0.056" size="0.0245 0.014 0.0055"/>
          <joint name="BLJ2" type="hinge" pos="0 0 0" axis="1 0 0" limited="true" range="-2.14 0"/>
          <site name="BLtip" type="sphere" pos="0 0 .076" size="0.01" rgba=".3 .3 1 1"/>
        </body>
      </body>
    </body>
  </body>
</mujocoinclude>
